<?xml version="1.0" ?>
<!-- =================================================================================== -->
<!-- |    This document was autogenerated by xacro from feeding_utensil.xacro          | -->
<!-- |    EDITING THIS FILE BY HAND IS NOT RECOMMENDED                                 | -->
<!-- =================================================================================== -->
<robot name="feeding_utensil">
  <!-- <joint name="${prefix}feeding_utensil_joint" type="fixed">
          <parent link="${parent}"/>
          <child link="${prefix}forkbase"/>
          <origin rpy="0.0 0.0 0.0" xyz="0.0 0.0 0.0"/>
    </joint> -->
  <link name="forkbase">
    <inertial>
      <origin rpy="0 0 0" xyz="0 0 0"/>
      <mass value="0.072775"/>
      <inertia ixx="1.821E-05" ixy="-4.1084E-09" ixz="-1.448E-07" iyy="1.062E-05" iyz="-1.5136E-09" izz="1.0557E-05"/>
    </inertial>
    <visual>
      <origin rpy="0 0 0" xyz="0 0 0"/>
      <geometry>
        <mesh filename="utensil_base.stl"/>
      </geometry>
      <material name="">
        <color rgba="0.75294 1 0.75294 1"/>
      </material>
    </visual>
    <!-- <collision>
      <origin rpy="0 0 0" xyz="0 0 0"/>
      <geometry>
        <mesh filename="utensil_base.stl"/>
      </geometry>
    </collision> -->
  </link>
  <link name="forkpitch">
    <inertial>
      <origin rpy="0 0 0" xyz="0 0 0"/>
      <mass value="0.072775"/>
      <inertia ixx="1.821E-05" ixy="-4.1084E-09" ixz="-1.448E-07" iyy="1.062E-05" iyz="-1.5136E-09" izz="1.0557E-05"/>
    </inertial>
    <visual>
      <origin rpy="0 0 0" xyz="0 0 0"/>
      <geometry>
        <mesh filename="pitch_link.stl"/>
      </geometry>
      <material name="">
        <color rgba="1 0.50196 0.50196 1"/>
      </material>
    </visual>
    <!-- <collision>
      <origin rpy="0 0 0" xyz="0 0 0"/>
      <geometry>
        <mesh filename="pitch_link.stl"/>
      </geometry>
    </collision> -->
  </link>
  <joint name="forkpitch_joint" type="revolute">
    <origin rpy="0 0 0" xyz="0.11 0.0 -0.087"/>
    <parent link="forkbase"/>
    <child link="forkpitch"/>
    <axis xyz="0 0 -1"/>
    <limit effort="0.93" lower="-1.5707963267948966" upper="1.5707963267948966" velocity="8.4"/>
  </joint>
  <link name="forkroll">
    <inertial>
      <origin rpy="0 0 0" xyz="0.011976 -0.00049403 -0.00081409"/>
      <mass value="0.072775"/>
      <inertia ixx="1.821E-05" ixy="-4.1084E-09" ixz="-1.448E-07" iyy="1.062E-05" iyz="-1.5136E-09" izz="1.0557E-05"/>
    </inertial>
    <visual>
      <origin rpy="0 0 0" xyz="0 0 0"/>
      <geometry>
        <mesh filename="roll_link.stl"/>
      </geometry>
      <material name="">
        <color rgba="1 1 1 1"/>
      </material>
    </visual>
    <!-- <collision>
      <origin rpy="0 0 0" xyz="0 0 0"/>
      <geometry>
        <mesh filename="roll_link.stl"/>
      </geometry>
    </collision> -->
  </link>
  <joint name="forkroll_joint" type="continuous">
    <origin rpy="-1.570796 0 0" xyz="0.0151 0.0 0.0095  "/>
    <parent link="forkpitch"/>
    <child link="forkroll"/>
    <axis xyz="1 0 0"/>
    <limit effort="0.93" velocity="8.4"/>
  </joint>
  <link name="feeding_utensil_tip">
    <inertial>
      <origin rpy="0 0 0" xyz="0 0 0"/>
      <mass value="0"/>
      <inertia ixx="0" ixy="0" ixz="0" iyy="0" iyz="0" izz="0"/>
    </inertial>
  </link>
  <joint name="joint_feeding_utensil_tip" type="fixed">
    <parent link="forkroll"/>
    <child link="feeding_utensil_tip"/>
    <axis xyz="0 0 0"/>
    <limit effort="2000" lower="0" upper="0" velocity="1"/>
    <!-- <origin rpy="0 0 0" xyz="0.095 0.007 0.0"/> -->
    <!-- <origin rpy="0 0 0" xyz="0.097 0.00 -0.002"/> -->
    <origin rpy="0 0 0" xyz="0.1 -0.013 -0.002"/>
  </joint>
  <link name="forque_tip">
    <inertial>
      <origin rpy="0 0 0" xyz="0 0 0"/>
      <mass value="0"/>
      <inertia ixx="0" ixy="0" ixz="0" iyy="0" iyz="0" izz="0"/>
    </inertial>
  </link>
  <joint name="joint_fork_tip" type="fixed">
    <parent link="feeding_utensil_tip"/>
    <child link="forque_tip"/>
    <axis xyz="0 0 0"/>
    <limit effort="2000" lower="0" upper="0" velocity="1"/>
    <origin rpy="1.570796 0 1.570796" xyz="0.0 0 0.0"/>
  </joint>
</robot>

